Workbook
Name Total: Principal!$H$22
Name MDO: Principal!$I$4
Name Material.Soco: 'Página2'!$A$33:$A$34
Name Material.Peitoril: 'Página2'!$A$5:$A$6
Name Material.CubaEsculpida: 'Página2'!$A$25:$A$26
Name Material.RequadroJanela: 'Página2'!$A$17:$A$18
Name Material.TentoDoBox: 'Página2'!$A$7:$A$8
Name Material.ForraçãoBanheira: 'Página2'!$A$37:$A$38
Name Material.Alizar: 'Página2'!$A$39:$A$40
Name a: Principal!$B$22:$H$33
Name Material.Bancada: 'Página2'!$A$1:$A$2
Name Imp.TOTMAT: 'Impressão'!$E$16
Name Material.Ilharga: 'Página2'!$A$3:$A$4
Name Imp.TOTCRED: 'Impressão'!$E$18
Name Material.Filete: 'Página2'!$A$29:$A$30
Name AjudaMDO2: 'Página1'!$B$66
Name Materiais: 'Lista de Materiais'!$B$3:$B$125
Name Material.Rodapé: 'Página2'!$A$19:$A$20
Name Material.Escada: 'Página2'!$A$23:$A$24
Name Material.RequadroPorta: 'Página2'!$A$13:$A$14
Name Material.Forração: 'Página2'!$A$35:$A$36
Name Material.Piso: 'Página2'!$A$21:$A$22
Name Imp.FR: 'Impressão'!$E$19
Name Frete: Principal!$I$2
Name Material.Soleira: 'Página2'!$A$9:$A$10
Name Material.Chapim: 'Página2'!$A$11:$A$12
Name BDMateriais: 'Lista de Materiais'!$B$2:$C$125
Name Credito: Principal!$I$7
Name b: 'Lista Salva'!$B$1:$H$31
Name AjudaMDO: Principal!$H$5
Name Material.Mesa: 'Página2'!$A$27:$A$28
Name Material.BalcãoSeco: 'Página2'!$A$31:$A$32
Name Imp.MDOC: 'Impressão'!$E$17
Name Trabalhos: 'Página2'!$D$3:$D$30
Name Imp.TOT: 'Impressão'!$E$20
Name Material.Nicho: 'Página2'!$A$15:$A$16

Sheet Página2
A1: Materiais | D1: =IF(Principal!F2="Bancada",13,IF(Principal!F2="Ilharga",12,IF(Principal!F2="Cuba",11,IF(Principal!F2="Peitoril",10,IF(Principal!F2="Tento do Box",9,IF(Principal!F2="Soleira/Filete",8,IF(Principal!F2="Chapim",7,IF(Principal!F2="Requadro Porta",6,IF(Principal!F2="Nicho",5,IF(Principal!F2="Requadro Janela",4,IF(Principal!F2="Rodapé",3,IF(Principal!F2="Piso",2,IF(Principal!F2="Escada",1,0))))))))))))) -> 13
A2: =Principal!$B$7 -> AMARELO FLORENÇA | B2: Bancada | D2: TRABALHOS
A3: Materiais | D3: Bancada
A4: =Principal!B11 -> Front lateral? | B4: Ilharga | D4: Ilharga
A5: Materiais | D5: Cuba
A6: =Principal!$B$13 -> Total | B6: Peitoril | D6: Peitoril
A7: Materiais | D7: Tento do Box
A8: =Principal!B16 | B8: Tento do Box | D8: Soleira
A9: Materiais | D9: Chapim
A10: =Principal!B13 -> Total | B10: Soleira | D10: Requadro Porta
A11: Materiais | D11: Nicho
A12: =Principal!B16 | B12: Chapim | D12: Requadro Janela
A13: Materiais | D13: Rodapé
A14: =Principal!B13 -> Total | B14: Requadro Porta | D14: Piso
A15: Materiais | D15: Escada
A16: =Principal!B7 -> AMARELO FLORENÇA | B16: Nicho | D16: Cuba Esculpida
A17: Materiais | D17: Mesa
A18: =Principal!B14 | B18: Requadro Janela | D18: Filete
A19: Materiais | D19: Balcão Seco
A20: =Principal!B16 | B20: Rodapé | D20: Soco
A21: Materiais | D21: Forração
A22: =Principal!B16 | B22: Piso | D22: Forração Banheira
A23: Materiais | D23: Alizar
A24: =Principal!B5 -> BANCADA | B24: Escada
A25: Materiais
A26: =Principal!B12 -> Front? | B26: Cuba Esculpida
A27: Materiais
A28: =Principal!$B$7 -> AMARELO FLORENÇA | B28: Mesa
A29: Materiais
A30: =Principal!B13 -> Total | B30: Filete
A31: Materiais
A32: =Principal!B7 -> AMARELO FLORENÇA | B32: Balcão Seco
A33: Materiais
A34: =Principal!B16 | B34: Soco
A35: Materiais
A36: =Principal!B16 | B36: Forração
A37: Materiais
A38: =Principal!B11 -> Front lateral? | B38: Forração Banheira
A39: Materiais
A40: =Principal!B10 -> Saia frontal? | B40: Alizar

Sheet Principal
A1: b | I1: 300
B2: TABELA DE TRABALHOS | F2: Bancada | H2: Frete: | I2: 0
H4: Mão de Obra | I4: 0.3
B5: BANCADA | H5: FALSE
B6: m² | C6: 2,00 | D6: 0,50 | E6: Quantidade | F6: 1
B7: AMARELO FLORENÇA | E7: 800 | H7: Abater do Total (Crédito) | I7: 0
B8: 1.2 | D8: =IF(E8=TRUE,"111%","100%") -> 111% | E8: TRUE
B9: Saia lateral? | C9: 0
B10: Saia frontal? | C10: 1 | D10: 1,50 | E10: 0,10
B11: Front lateral? | C11: 1 | D11: 0,50 | E11: 0,20
B12: Front? | C12: 1,50 | D12: 0,20 | E12: Quantidade | F12: 1
B13: Total | C13: =IF(F6>1,F6&" Bancadas de "&C6&"x"&D6&"m²",IF(F6=1,"Bancada: "&C6&"x"&D6&"m²"," ")) -> Bancada: 2,00x0,50m² | D13: =IF(D6>0,(C6*D6)*B8*D8*E7*F6," ") -> 1065.6
C14: =IF(C9>1," + "&C9&" Saias Lat. de "&D9&"x"&E9&" m²",IF(C9=1," + "&C9&" Saia Lat. "&D9&"x"&E9&" m²","")) | D14: =IF(E9>0,(D9*E9)*B8*D8*E7*C9," ")
C15: =IF(C10>1," + "&C10&" Saias frontais de "&D10&"x"&E10&"m²",IF(C10=1," + "&C10&" Saia frontal "&D10&"x"&E10&"m²","")) -> + 1 Saia frontal 1,50x0,10m² | D15: =IF(E10>0,D10*E10*B8*D8*E7*C10," ") -> 159.84
C16: =IF(C11>1," + "&C11&" Frontes lat. de "&D11&"x"&E11&"m²",IF(C11=1," + "&C11&" Front lat. "&D11&"x"&E11&"m²","")) -> + 1 Front lat. 0,50x0,20m² | D16: =IF(E11>0,C11*D11*E11*B8*D8*E7," ") -> 106.56
C17: =IF(F12>1," + "&F12&" Frontes de "&C12&"x"&D12&"m²",IF(F12=1," + Front de "&C12&"x"&D12&"m²"," ")) -> + Front de 1,50x0,20m² | D17: =IF(D12>0,C12*D12*B8*D8*E7*F12," ") -> 319.68
B18: =C13&C14&C15&C16&C17 -> Bancada: 2,00x0,50m² + 1 Saia frontal 1,50x0,10m² + 1 Front lat. 0,50x0,20m² + Front de 1,50x0,20m² | D18: =SUM(D13:D17) -> 1651.68
A20: Rua Jacamim, nº 8 – Jardim Anhangá – Duque de Caxias – RJ – Tels: (021) 98371-0067 / 98090-0260
B22: LISTA GERAL | F22: TOTAL | H22: =SUM(F22:F33) -> 5964.9855
B23: BANHO 2 | F23: CINZA PRIME
B24: Bancada: 1,50x0,50m² + 1 Saia Lat. 0,50x0,10 m² + 1 Saia frontal 1,50x0,10m² + 1 Front lat. 0,50x0,20m² + Front de 1,50x0,20m² | F24: 1618.38
B25: Tento do Box: 2x 1,80x0,10m² | F25: 431.568
B26: Nicho: 2 peças 0,40x0,10m², 2 peças 1,20x0,10m² + Fundo de 1,20x0,40m² | F26: 959.04
B27: Filete: 0,70x0,05m² | F27: 38.4615
B28: BANHO MASTER | F28: BRANCO PREMIER
B29: Filete: 0,70x0,05m² | F29: 34.188
B30: Nicho: 2 peças 0,60x0,10m², 2 peças 1,20x0,10m² + Fundo de 1,20x0,60m² | F30: 1150.848
B31: Tento do Box: 2x 2,00x0,10m² | F31: 372.96
B32: Bancada em L: 1,60x0,45m² + 1 Saia frontal 1,60x0,10m² + Front de 1,60x0,20m²+Bancada: 0,67x0,25m² + 1 Saia frontal 0,67x0,10m² + 1 Front lat. 0,25x0,20m² + Front de 0,67x0,20m² | F32: 1359.54

Sheet Impressão
A1: ilo
D7: ="Rio de Janeiro, "&DAY(B142)&" de "&LOWER(TEXT(B142,"MMMM")) & " de " & YEAR(B142) -> Rio de Janeiro, 28 de abril de 2026
A8: Ao
A13: Conforme sua solicitação, apresentamos a seguir proposta para apreciação de V.S.ª, quanto ao fornecimento de granito para sua obra. Informamos ainda, prazo de entrega e condições de pagamento.
A16: TOTAL MATERIAL | E16: =Total -> 5964.9855
A17: M.O COLOCAÇÃO | E17: =IF(MDO*Total>1200,MDO*Total*AjudaMDO2,1200*AjudaMDO2) -> 0
A18: CREDITO | E18: =Credito -> 0
A19: FRETE | E19: =Frete -> 0
A20: TOTAL | E20: =Total+Frete+IF(MDO*Total>1200,MDO*Total*AjudaMDO2,1200*AjudaMDO2)-Credito -> 5964.9855
A21: . Prazo de entrega: A combinar.
A22: . Condições de pgto: A combinar.
A23: =". Frete: R$ "&Frete&" por conta do cliente." -> . Frete: R$ 0 por conta do cliente.
A24: . Não fornecemos cubas de louça, torneiras e acessórios. Não fazemos furo de torneira em cubas de louça, somente em pedra.
A25: . Todo material necessário para colocação é de reponsabilidade do cliente.
A26: . Para depósito: Banco Itaú ag.9285 - conta 99559-4 - FG MONTES ME – PIX : marmorariahelomar@gmail.com
A29: .(*) Validade da proposta: 20 dias para materiais nacionais.
A30: . (**) Validade da proposta: 02 dias para materiais importados em função da variação do dólar/euro.
A33: OBSERVAÇÕES:
A34: . Todo o faturamento terá como base os valores de m² e ml, podendo haver modificações após medição no local.
A36: . Todo o material aqui proposto é de origem mineral, portanto está sujeito a veios e variações de tonalidades.
A38: (*) Este prazo muda se o material for nanoglass ou marmoglass que passa a ser de até 30 dias úteis. Se tiver cuba esculpida, então passa para até 35 dias úteis.
A43: . Valor mínimo cobrado para colocação e ou reparo é de R$ 1.200,00 ( Hum mil e duzentos reais );
A45: . Toda cuba esculpida é trabalho artesanal e sendo assim, o valor cobrado parte de R$ 1.000,00 ( Hum mil reais);
A48: . É necessário que o colocador ou responsável pela colocação esteja(m) no local para acompanhar a medição que será realizada em uma única etapa e cada profissional tem uma maneira própria de trabalhar;
... A136: Aceite do cliente:
A139: Data: | B139: =TODAY() -> 46140 | D139: CPF/CNPJ:
A142: Data: | B142: =TODAY() -> 46140 | D142: CPF/CNPJ:

Sheet Lista de Materiais
A1: 1200
B2: Materiais | C2: Preços
B3: ALBA PEITA CINZA | C3: 2000
B4: AMARELO FLORENÇA | C4: 500
B5: AMARELO ICARAI | C5: 500
B6: AMARELO MARACUJA | C6: 600
B7: AMARELO ORNAMENTAL | C7: 500
B8: AMÊNDOA | C8: 500
B9: ARDOSIA | C9: 600
B10: AS DE PAUS | C10: 800
B11: AZUL MACAÚBAS | C11: 2500
B12: BRANCO CEARÁ | C12: 850
B13: BCO CEARÁ ESCOVADO | C13: 950
B14: BCO CHOCOLATE | C14: 650
... B117: VRD UBATUBA FLAMEADO | C117: 400

Sheet Lista Salva
B2: DESPENSA | F2: MÁRMORE BRANCO COMUM
B3: 3 prateleiras de 0,50x0,30m² | F3: 287.2125
B4: 5 prateleiras de 0,60x0,30m² | F4: 574.425
B5: 5 prateleiras de 1,17x0,30m² | F5: 1120.1287
B6: PEITORIS | F6: MÁRMORE BCO COMUM
B7: Peitoril quarto 2: 1,50x0,20m² | F7: 191.475
B8: Peitoril quarto 1: 1,74x0,20m² | F8: 222.111
B9: Peitoril cozinha: 0,82x0,20m² + 1,75x0,20m² + 0,60x0,20m² | F9: 404.65
B10: Peitoril sala: 1,54x0,20m² + 1,76x0,20m² | F10: 421.24
B11: BANHO SUÍTE | F11: QUARTZO BRANCO
B12: Peitoril: 0,54x0,17m² | F12: 152.33751
B13: Tento do Box: 2x 1,40x0,10x0,04m² | F13: 484.848
B14: Filete: 0,74x0,035m² | F14: 58.7301
B15: Bancada: 0,80x0,55m² + 1 Saia Lat. 0,55x0,10 m² + 1 Saia frontal 0,80x0,10m² + 1 Front lat. 0,55x0,10m² + Front de 0,80x0,10m² | F15: 1229.436
B16: BANHO SOCIAL | F16: QUARTZO BRANCO
B17: Peitoril: 0,64x0,17m² | F17: 180.54816
B18: Tento do Box: 2x 1,20x0,10x0,04m² | F18: 415.584
B19: Filete: 0,74x0,035m² | F19: 58.7301
B20: Bancada: 0,70x0,50m² + 1 Saia Lat. 0,50x0,10 m² + 1 Saia frontal 0,70x0,10m² + 1 Front lat. 0,50x0,10m² + Front de 0,70x0,10m² | F20: 1021.644
B21: ÁREA DE SERVIÇO | F21: PRETO S. GABRIEL
B22: Bancada: 2,11x0,65m² + 1 Saia frontal 2,11x0,04m² + 2 Frontes lat. de 0,65x0,10m² + Front de 2,11x0,10m² | F22: 1914.7766
B23: COZINHA | F23: PRETO S. GABRIEL
B24: Bancada: 2,12x0,65m² + 1 Saia frontal 2,12x0,04m² + 2 Frontes lat. de 0,65x0,10m² + Front de 2,12x0,10m² | F24: 1923.1949
C31: TAMPO MESA
C32: m² | F32: Quantidade
C33: AMARELO FLORENÇA | F33: =IFERROR(DGET(BDMateriais,'Lista de Materiais'!$C$2,Material.Mesa),"Não há preço na tabela para um material desse nome") -> 500 | H33: % no Pé:
C34: =IFS(F37=TRUE(),1.5,D37=TRUE(),1.2,E32>-1,1.2) -> 1.2 | E34: =IF(F34=TRUE,"111%","100%") -> 111% | F34: TRUE
C35: Saia lateral? | D35: 0 | H35: Pé?
C36: Saia frontal? | D36: 0
C37: Sarim? | D37: FALSE
C38: Total | D38: =IF(G31>1,G31&" Mesas com Tampo de "&D32&"x"&E32&"m²",IF(G31=1,"Mesa: Tampo de "&D32&"x"&E32&"m²"," "))&IF(F37=TRUE()," c/ Sarim","")&IF(D37=TRUE()," c/ Saia","") | E38: =IF(E32>0,(D32*E32)*D34*E34*F33*G31," ")
D39: =IF(K35>0," + Pé "&I35&" c/ total de "&J35&"x"&K35&"m²","") | E39: =IF(K35>0,(J35*K35)*I33*E34*F33," ")
C40: =E38&E39 | E40: =SUM(E38:E39) -> 0

Sheet Página1
P2: NICHO
A3: BANCADA | P3: Altura | R3: Profundidade
A4: m² | D4: Quantidade | P4: Comprimento | R4: Quantidade
A5: AMARELO FLORENÇA | D5: =IFERROR(DGET(BDMateriais,'Lista de Materiais'!$C$2,Material.Bancada),"Não há preço na tabela para um material desse nome") -> 500 | P5: AMARELO FLORENÇA | S5: =IFERROR(DGET(BDMateriais,'Lista de Materiais'!$C$2,Material.Nicho),"Não há preço na tabela para um material desse nome") -> 500
A6: 1.2 | C6: =IF(D6=TRUE,"111%","100%") -> 111% | D6: TRUE | P6: 1.2 | R6: =IF(S6=TRUE,"111%","100%") -> 111% | S6: TRUE
A7: Saia lateral? | B7: 0 | P7: Fundo? | S7: Quantidade
A8: Saia frontal? | B8: 0 | P8: Alizar lateral? | Q8: 0
A9: Front lateral? | B9: 0 | K9: SOLEIRA | P9: Alizar superior / inferior? | Q9: 0
A10: Front? | D10: Quantidade | K10: m² | N10: Quantidade | P10: Prateleira? | Q10: 0
A11: Total | B11: =IF(E4>1,E4&" Bancadas de "&B4&"x"&C4&"m²",IF(E4=1,"Bancada: "&B4&"x"&C4&"m²"," ")) | C11: =IF(C4>0,(B4*C4)*A6*C6*D5*E4," ") | K11: AMARELO FLORENÇA | N11: =IFERROR(DGET(BDMateriais,'Lista de Materiais'!$C$2,Material.Soleira),"Não há preço na tabela para um material desse nome") -> Não há preço na tabela para um material desse nome | P11: Total | Q11: =IF(S4>1,S4&" Nichos com 2 peças "&Q3&"x"&S3&"m², 2 peças "&Q4&"x"&S3&"m²",IF(S4=1,"Nicho: 2 peças "&Q3&"x"&S3&"m², 2 peças "&Q4&"x"&S3&"m²"," ")) | R11: =IF(Q3>0,(Q3+Q4)*2*S3*P6*R6*S5*S4," ")
B12: =IF(B7>1," + "&B7&" Saias Lat. de "&C7&"x"&D7&" m²",IF(B7=1," + "&B7&" Saia Lat. "&C7&"x"&D7&" m²","")) | C12: =IF(D7>0,(C7*D7)*A6*C6*D5*B7," ") | K12: =IF(ISNUMBER(N13),1.2,1.1) -> 1.1 | M12: =IF(N12=TRUE,"111%","100%") -> 111% | N12: TRUE | Q12: =IF(T7>1," + "&T7&" Fundos de "&Q7&"x"&R7&"m²",IF(T7=1," + Fundo de "&Q7&"x"&R7&"m²"," ")) | R12: =IF(R7>0,(Q7*R7)*P6*R6*S5*T7," ") | U12: RODAPÉ
B13: =IF(B8>1," + "&B8&" Saias frontais de "&C8&"x"&D8&"m²",IF(B8=1," + "&B8&" Saia frontal "&C8&"x"&D8&"m²","")) | C13: =IF(D8>0,C8*D8*A6*C6*D5*B8," ") | K13: Saia? | N13: Quantidade | Q13: =IF(Q8>1," + "&Q8&" Alizares lat. de "&R8&"x"&S8&"m²",IF(Q8=1," + "&Q8&" Alizar lat. "&R8&"x"&S8&"m²"," ")) | R13: =IF(S8>0,Q8*(R8*S8)*P6*R6*S5," ") | U13: m² | X13: Quantidade
B14: =IF(B9>1," + "&B9&" Frontes lat. de "&C9&"x"&D9&"m²",IF(B9=1," + "&B9&" Front lat. "&C9&"x"&D9&"m²","")) | C14: =IF(D9>0,B9*C9*D9*A6*C6*D5," ") | F14: CUBA | K14: Total | L14: =IF(O10>1,O10&" Soleiras de "&L10&"x"&M10&"m²",IF(O10=1,"Soleira: "&L10&"x"&M10&"m²"," ")) | M14: =IF(M10>0,(L10*M10)*K12*M12*N11*O10," ") | Q14: =IF(Q9>1," + "&Q9&" Alizares sup./inf. de "&R9&"x"&S9&"m²",IF(Q9=1," + "&Q9&" Alizar sup./inf. "&R9&"x"&S9&"m²"," ")) | R14: =IF(S9>0,Q9*(R9*S9)*P6*R6*S5," ") | U14: AMARELO FLORENÇA | X14: =IFERROR(DGET(BDMateriais,'Lista de Materiais'!$C$2,Material.Rodapé),"Não há preço na tabela para um material desse nome") -> Não há preço na tabela para um material desse nome
B15: =IF(E10>1," + "&E10&" Frontes de "&B10&"x"&C10&"m²",IF(E10=1," + Front de "&B10&"x"&C10&"m²"," ")) | C15: =IF(C10>0,B10*C10*A6*C6*D5*E10," ") | F15: - | G15: - | H15: Quantidade | L15: =IF(O13>1," + "&O13&" Saias de "&L13&"x"&M13&"m²",IF(O13=1,"+ Saia de "&L13&"x"&M13&"m²"," ")) | M15: =IF(M13>0,(L13*M13)*K12*M12*N11*O13," ") | Q15: =IF(Q10>1," + "&Q10&" Prateleiras de "&R10&"x"&S10&"m²",IF(Q10=1," + "&Q10&" Prateleira "&R10&"x"&S10&"m²"," ")) | R15: =IF(R10>0,(S10*R10)*P6*R6*S5*Q10," ") | U15: 1.1 | W15: =IF(X15=TRUE,"111%","100%") -> 111% | X15: TRUE
A16: =B11&B12&B13&B14&B15 | C16: =SUM(C11:C15) -> 0 | F16: =IF(I15=1,"Cuba: Tipo "&F15&" "&G15,IF(I15>1,I15&" Cubas: Tipo "&F15&" "&G15,"")) | H16: =IF(F16="Cuba: Tipo 1 Rasa",100,IF(F16="Cuba: Tipo 1 Funda",130,IF(F16="Cuba: Tipo 2 Rasa",130,IF(F16="Cuba: Tipo 2 Funda", 190,IF(F16=I15&" Cubas: Tipo 1 Rasa",100*I15,IF(F16=I15&" Cubas: Tipo 1 Funda",130*I15,IF(F16=I15&" Cubas: Tipo 2 Rasa",I15*130,IF(F16=I15&" Cubas: Tipo 2 Funda",190*I15,"")))))))) | K16: =L14&L15 | M16: =SUM(M14:M15) -> 0 | P16: =Q11&Q12&Q13&Q14&Q15 | R16: =SUM(R11:R15) -> 0 | U16: =IF(Y13>1,Y13&" Rodapés de "&V13&"x"&W13&"m²",IF(Y13=1,"Rodapé: "&V13&"x"&W13&"m²"," ")) | W16: =IF(Y13>0,Y13*(V13*W13)*U15*W15*X14," ")
A23: ILHARGA
A24: m² | D24: Quantidade
A25: AMARELO FLORENÇA | D25: =IFERROR(DGET(BDMateriais,'Lista de Materiais'!$C$2,Material.Ilharga),"Não há preço na tabela para um material desse nome") -> Não há preço na tabela para um material desse nome | F25: PEITORIL | P25: REQUADRO JANELA
A26: =IF(B28=TRUE(),1.3,1.2) -> 1.2 | C26: =IF(D26=TRUE,"111%","100%") -> 111% | D26: TRUE | F26: m² | I26: Quantidade | P26: Altura | R26: Profundidade
A27: Saia? | B27: 0 | F27: AMARELO FLORENÇA | I27: =IFERROR(DGET(BDMateriais,'Lista de Materiais'!$C$2,Material.Peitoril),"Não há preço na tabela para um material desse nome") -> Não há preço na tabela para um material desse nome | P27: Comprimento | R27: Quantidade
A28: Polir 2 faces? | B28: FALSE | F28: =IF(H29>0,1.2,1.15) -> 1.15 | H28: =IF(I28=TRUE,"111%","100%") -> 111% | I28: TRUE | K28: CHAPIM | P28: AMARELO FLORENÇA | S28: =IFERROR(DGET(BDMateriais,'Lista de Materiais'!$C$2,Material.RequadroJanela),"Não há preço na tabela para um material desse nome") -> Não há preço na tabela para um material desse nome | U28: PISO
A29: Dupla? | B29: FALSE | F29: Saia? | G29: 0 | K29: m² | N29: Quantidade | P29: =IF(R30=TRUE(),1.2,IF(R31=TRUE(),1.2,1.2)) -> 1.2 | R29: =IF(S29=TRUE,"111%","100%") -> 111% | S29: TRUE | U29: m² | X29: Quantidade
A30: Total | B30: =IF(E24>1,E24&" Ilhargas de "&B24&"x"&C24&"m²",IF(E24=1,"Ilharga: "&B24&"x"&C24&"m²","")&IF(B29=TRUE()," dupla","")&IF(B28=TRUE()," (2 faces polidas)","")) | C30: =IF(B29=FALSE(),(B24*C24)*A26*C26*D25*E24,2*(B24*C24)*A26*C26*D25*E24) -> #VALUE! | F30: Total | G30: =IF(J26>1,J26&" Peitoris de "&G26&"x"&H26&"m²",IF(J26=1,"Peitoril: "&G26&"x"&H26&"m²"," ")) | H30: =IF(H26>0,(G26*H26)*F28*H28*I27*J26," ") | K30: AMARELO FLORENÇA | N30: =IFERROR(DGET(BDMateriais,'Lista de Materiais'!$C$2,Material.Chapim),"Não há preço na tabela para um material desse nome") -> Não há preço na tabela para um material desse nome | P30: Só lateral? | R30: FALSE | U30: AMARELO FLORENÇA | X30: =IFERROR(DGET(BDMateriais,'Lista de Materiais'!$C$2,Material.Piso),"Não há preço na tabela para um material desse nome") -> Não há preço na tabela para um material desse nome
B31: =IF(B27>1," + "&B27&" Saias de "&C27&"x"&D27&"m²",IF(B27=1," + "&B27&" Saia "&C27&"x"&D27&"m²"," ")) | C31: =IF(D27>0,B27*(C27*D27)*A26*C26*D25," ") | G31: =IF(G29>1," + "&G29&" Saias de "&H29&"x"&I29&"m²",IF(G29=1," + "&G29&" Saia de "&H29&"x"&I29&"m²"," ")) | H31: =IF(I29>0,G29*(H29*I29)*F28*H28*I27," ") | K31: 1.1 | M31: =IF(N31=TRUE,"111%","100%") -> 111% | N31: TRUE | P31: Só peitoril? | R31: FALSE | U31: 1.1 | W31: =IF(X31=TRUE,"111%","100%") -> 111% | X31: TRUE
A32: =B30&B31 | C32: =SUM(C30:C31) -> #VALUE! | F32: =G30&G31 | H32: =SUM(H30:H31) -> 0 | K32: =IF(O29>1,O29&" Chapins de "&L29&"x"&M29&"m²",IF(O29=1,"Chapim: "&L29&"x"&M29&"m²"," ")) | M32: =IF(M29>0,(L29*M29)*K31*M31*N30*O29," ") | P32: =IF(R30=TRUE(),"Requadro de Janela na lateral ("&S27&"x) de "&Q26&"x"&S26&"m² ",IF(R31=TRUE(),"Requadro de Janela peitoril ("&S27&"x) de "&Q27&"x"&S26&"m² ",IF(R32>0,"("&S27&"x) "&"Requadro Janela: 2 peças "&Q26&"x"&S26&"m², 2 peças "&Q27&"x"&S26&"m²",""))) -> #VALUE! | R32: =IF(R30=TRUE(),Q26*S26*S27*P29*R29*S28,IF(R31=TRUE(),Q27*S26*S27*P29*R29*S28,(Q26+Q27)*2*S26*P29*R29*S28*S27)) -> #VALUE! | U32: =IF(Y29>1,Y29&" Peças de Piso de "&V29&"x"&W29&"m²",IF(Y29=1,"Piso: "&V29&"x"&W29&"m²"," ")) | W32: =IF(Y29>0,Y29*(V29*W29)*U31*W31*X30," ")
U33: ESCADA
U34: m² | X34: Quantidade
P35: MESA | U35: AMARELO FLORENÇA | X35: =IFERROR(DGET(BDMateriais,'Lista de Materiais'!$C$2,Material.Escada),"Não há preço na tabela para um material desse nome") -> Não há preço na tabela para um material desse nome
P36: m² | S36: Quantidade | U36: =IF(ISNUMBER(X37),1.2,1.2) -> 1.2 | W36: =IF(X36=TRUE,"111%","100%") -> 111% | X36: TRUE
P37: AMARELO FLORENÇA | S37: =IFERROR(DGET(BDMateriais,'Lista de Materiais'!$C$2,Material.Mesa),"Não há preço na tabela para um material desse nome") -> 500 | U37: Saia? | X37: Quantidade
P38: % no Tampo: | Q38: =IF(Q42=TRUE(),1.5,1.2) -> 1.2 | R38: =IF(S38=TRUE,"111%","100%") -> 111% | S38: TRUE | U38: Espelho? | X38: Quantidade
A39: CUBA ESCULPIDA | P39: % no Pé: | Q39: =Ifs(Q43="Comum",1.2,Q43="Encaixado",1.2,Q43="Caixinha",1.3) -> 1.2 | U39: Degraus Especiais?
A40: Largura | C40: Profundidade | K40: REQUADRO PORTA | P40: Saia lateral? | Q40: 0 | U40: Saia Especial?
A41: Comprimento | C41: Quantidade | K41: Altura | M41: Profundidade | P41: Saia frontal? | Q41: 0 | U41: Espelho Especial?
A42: AMARELO FLORENÇA | D42: =IFERROR(DGET(BDMateriais,'Lista de Materiais'!$C$2,Material.CubaEsculpida),"Não há preço na tabela para um material desse nome") -> Não há preço na tabela para um material desse nome | K42: Comprimento | M42: Quantidade | P42: Sarim? | Q42: FALSE | U42: Total | V42: =IF(Y34>1,Y34&" Degraus de "&V34&"x"&W34&"m²",IF(Y34=1,"Degrau "&V34&"x"&W34&"m²"," ")) | W42: =IF(Y34>0,Y34*(V34*W34)*U36*W36*X35," ")
A43: Preço da mão de obra | D43: 1000 | K43: AMARELO FLORENÇA | N43: =IFERROR(DGET(BDMateriais,'Lista de Materiais'!$C$2,Material.RequadroPorta),"Não há preço na tabela para um material desse nome") -> Não há preço na tabela para um material desse nome | P43: Pé? | Q43: Comum | V43: =IF(Y37>1," + "&Y37&" Saias de "&V37&"x"&W37&"m²",IF(Y37=1," + "&Y37&" Saia "&V37&"x"&W37&"m²"," ")) | W43: =IF(W37>0,(V37*W37)*U36*W36*X35*Y37," ")
A44: 1.2 | C44: =IF(D44=TRUE,"111%","100%") -> 111% | D44: TRUE | F44: TENTO DO BOX | K44: =IF(M45=TRUE(),1.2,IF(M46=TRUE(),1.2,1.2)) -> 1.2 | M44: =IF(N44=TRUE,"111%","100%") -> 111% | N44: TRUE | P44: Total | Q44: =IF(T36>1,T36&" Mesas com Tampo de "&Q36&"x"&R36&"m²",IF(T36=1,"Mesa: Tampo de "&Q36&"x"&R36&"m²"," "))&IF(Q42=TRUE()," c/ Sarim","") | R44: =IF(R36>0,(Q36*R36)*Q38*R38*S37*T36," ") | V44: =IF(Y38>1," + "&Y38&" Espelhos de "&V38&"x"&W38&"m²",IF(Y38=1," + "&Y38&" Espelho "&V38&"x"&W38&"m²"," ")) | W44: =IF(W38>0,(V38*W38)*U36*W36*X35*Y38," ")
A45: Fundo falso? | D45: Quantidade | F45: 2x m² | I45: Quantidade | K45: Laterais? | M45: FALSE | Q45: =IF(Q40>1," + "&Q40&" Saias Lat. de "&R40&"x"&S40&" m²",IF(Q40=1," + "&Q40&" Saia Lat. "&R40&"x"&S40&" m²","")) | R45: =IF(S40>0,(R40*S40)*Q38*R38*S37*Q40," ") | V45: =IF(X39>0," + Degrau(s) Esp. "&W39&"x"&X39&"m²"," ") | W45: =IF(X39>0,(W39*X39)*U36*W36*X35," ")
A46: Total | B46: =IF(D41>1,D41&" Cubas Esculpidas de 2 peças "&B40&"x"&D40&"m², 2 peças "&B41&"x"&D40&"m² c/ fundo de "&B40&"x"&B41&"m²",IF(D41=1,"Cuba Esculpida: 2 peças "&B40&"x"&D40&"m², 2 peças "&B41&"x"&D40&"m² c/ fundo de "&B40&"x"&B41&"m²","")) | C46: =IF(B40>0,2*(B40+B41)*D40*D42*A44*C44*D41," ") | F46: AMARELO FLORENÇA | I46: =IFERROR(DGET(BDMateriais,'Lista de Materiais'!$C$2,Material.TentoDoBox),"Não há preço na tabela para um material desse nome") -> Não há preço na tabela para um material desse nome | K46: Piso? | M46: FALSE | Q46: =IF(Q41>1," + "&Q41&" Saias frontais de "&R41&"x"&S41&"m²",IF(Q41=1," + "&Q41&" Saia frontal "&R41&"x"&S41&"m²","")) | R46: =IF(S41>0,(R41*S41)*Q38*R38*S37*Q41," ") | V46: =IF(X40>0," + Saia(s) Esp. "&W40&"x"&X40&"m²"," ") | W46: =IF(X40>0,(W40*X40)*U36*W36*X35," ")
B47: =IF(E45>1," + "&E45&" Fundos Falsos de "&B45&"x"&C45&"m²",IF(E45=1," + Fundo Falso de "&B45&"x"&C45&"m²","")) | C47: =IF(C45>0,B45*C45*A44*C44*D42*E45," ") | F47: 1.2 | H47: =IF(I47=TRUE,"111%","100%") -> 111% | I47: TRUE | K47: Superior? | M47: FALSE | Q47: =IF(S43>0," + Pé "&Q43&" c/ total de "&R43&"x"&S43&"m²","") | R47: =IF(S43>0,(R43*S43)*Q39*R38*S37," ") | V47: =IF(X41>0," + Espelho(s) esp. "&W41&"x"&X41&"m²"," ") | W47: =IF(X41>0,(W41*X41)*U36*W36*X35," ")
...
